<?xml version='1.0' encoding='UTF-8'?>
<!--URDF-->
<robot name='JumpRobot'>

    <link name="base">
        <inertial>
            <origin rpy="0 0 0" xyz="0 0 0"/>
            <mass value="0"/>
            <inertia ixx="0" ixy="0" ixz="0" iyy="0" iyz="0" izz="0"/>
        </inertial>
    </link>

    <link name="body_a">
        <visual>
            <origin xyz="0 0 0" rpy="0 0 0"/>
            <geometry>
                <mesh filename="pb_jump/model/meshes/body.stl"/>
            </geometry>
            <material name="green">
                <color rgba="0.2 1 0.2 1"/>
            </material>
        </visual>

        <collision>
            <origin xyz="0 0 0" rpy="0 0 0"/>
            <geometry>
               <mesh filename="pb_jump/model/meshes/body.stl"/>
            </geometry>
        </collision>

        <inertial>
            <origin xyz="0 0 0" rpy="0 0 0"/>
            <mass value="30.00" />
            <inertia ixx="0.038" ixy="0.0" ixz="0.0" iyy="0.046" iyz="0.0" izz="0.022" />
        </inertial>
    </link>

    <link name="upper_leg_a">
        <visual>
            <origin xyz="0 0 0" rpy="0 0 0"/>
            <geometry>
                <mesh filename="pb_jump/model/meshes/upper_leg.stl"/>
            </geometry>
            <material name="red">
                <color rgba="1 0 0 1"/>
            </material>
        </visual>

        <collision>
            <origin xyz="0 0 0" rpy="0 0 0"/>
            <geometry>
                <mesh filename="pb_jump/model/meshes/upper_leg.stl"/>
            </geometry>
        </collision>

        <inertial>
            <origin xyz="0 0 -0.127" rpy="0 0 0"/>
            <mass value="1.5" />
            <inertia ixx="0.0" ixy="0.0" ixz="0.0" iyy="6.8548e-04" iyz="0.0" izz="6.8548e-04" />
        </inertial>
    </link>

    <link name="lower_leg_a">
        <visual>
            <origin xyz="0 0 0" rpy="0 0 0"/>
            <geometry>
                <mesh filename="pb_jump/model/meshes/lower_leg.stl"/>
            </geometry>
            <material name="blue">
                <color rgba="0 0 1 1"/>
            </material>
        </visual>

        <collision>
            <origin xyz="0 0 0" rpy="0 0 0"/>
            <geometry>
                <mesh filename="pb_jump/model/meshes/lower_leg.stl"/>
            </geometry>
        </collision>

        <inertial>
            <origin xyz="0 0 -0.105" rpy="0 0 0"/>
            <mass value="1.5" />
            <inertia ixx="0.0" ixy="0.0" ixz="0.0" iyy="3.6750e-04" iyz="0.0" izz="3.6750e-04" />
        </inertial>
    </link>       


    <link name="foot">
        <origin xyz="0 0 0" rpy="0 0 0" />
            <visual>
                <origin xyz="0 0 0" rpy="0 0 0" />
                <geometry>
                    <mesh filename="pb_jump/model/meshes/foot.stl"/>
                </geometry>
                <material name="black">
                    <color rgba="0 0 0 0.85"/>
                </material>
        </visual>

        <collision>
            <origin xyz="0 0 0" rpy="0 0 0"/>
            <geometry>
                <mesh filename="pb_jump/model/meshes/foot.stl"/>
            </geometry>
        </collision>    

        <inertial>
            <origin rpy="0 0 0" xyz="0 0 0"/>
            <mass value="0.1"/>
            <inertia ixx="0" ixy="0" ixz="0" iyy="0" iyz="0" izz="0"/>
        </inertial>
    </link>

    <link name="dummy_link">
        <origin xyz="0 0 0" rpy="0 0 0" />
        <inertial>
            <origin rpy="0 0 0" xyz="0 0 0"/>
            <mass value="0.1"/>
            <inertia ixx="0" ixy="0" ixz="0" iyy="0" iyz="0" izz="0"/>
        </inertial>
    </link>

    <joint name="base_r" type="continuous">
        <parent link="base"/>
        <child link="dummy_link"/>
        <axis xyz="0 0 1"/>
        <origin xyz="0 0 0"/>
        <limit velocity="100" effort="100"/> 
    </joint>

    <joint name="base" type="prismatic">
        <parent link="dummy_link"/>
        <child link="body_a"/>
        <axis xyz="0 0 1"/>
        <origin rpy="0 0 0" xyz="0 5 0"/>
        <limit lower="0" upper="1.5" velocity="100" effort="100"/> 
    </joint>
 
    <joint name="hfe" type="revolute">
        <origin rpy="0 0 0" xyz="0 0 -0.125"/>
        <parent link="body_a"/>
        <child link="upper_leg_a"/>
        <axis xyz="0 1 0"/>
        <dynamics damping="0.1" friction="0" />
        <limit lower="-1.57" upper="1.57"/>
    </joint>

    <joint name="kfe" type="revolute">
        <origin rpy="0 0 0" xyz="0 0 -0.285"/>
        <parent link="upper_leg_a"/>
        <child link="lower_leg_a"/>
        <axis xyz="0 1 0"/>
        <dynamics damping="0.1" friction="0" />
        <limit lower="-2.18" upper="2.18"/>
    </joint>

    <joint name="fft" type="fixed">
        <origin rpy="0 0 0" xyz="0 0 -0.270"/>
        <parent link="lower_leg_a"/>
        <child link="foot"/>
    </joint>

</robot>
